Workbook

Sheet Diseño
A2: =VALUE(LEFT(C4,FIND(" - ",C4)-1)) -> 786 | B2: Diseño de Contenido Curricular
B4: Curso | C4: 786 - Sistemas Organizacionales y Gerenciales 1
B5: Periodo al que aplica | C5: Primer Semestre 2026
B8: No. | C8: Competencia | D8: Nombre de la Unidad | E8: Tema | F8: Subtema | G8: Mes | H8: Semana
B9: 1 | C9: valida metodologías de gestión del cambio y rediseño de procesos organizativos utilizando modelos de cambio organizativo y técnicas de reingeniería con el fin de garantizar la incorporación efectiva de las TIC | D9: 1 | E9: Evolución del sistema de información | F9: Definición de sistema de información | G9: febrero | H9: 2
B10: 2 | C10: valida metodologías de gestión del cambio y rediseño de procesos organizativos utilizando modelos de cambio organizativo y técnicas de reingeniería con el fin de garantizar la incorporación efectiva de las TIC | D10: 1 | E10: Evolución del sistema de información | F10: Historia de los sistemas de información | G10: febrero | H10: 2
B11: 3 | C11: valida metodologías de gestión del cambio y rediseño de procesos organizativos utilizando modelos de cambio organizativo y técnicas de reingeniería con el fin de garantizar la incorporación efectiva de las TIC | D11: 1 | E11: Evolución del sistema de información | F11: Tipos de sistemas de información | G11: febrero | H11: 2
B12: 4 | C12: valida metodologías de gestión del cambio y rediseño de procesos organizativos utilizando modelos de cambio organizativo y técnicas de reingeniería con el fin de garantizar la incorporación efectiva de las TIC | D12: 1 | E12: Evolución del sistema de información | F12: Importancia en la empresa | G12: febrero | H12: 2
B13: 5 | C13: valida metodologías de gestión del cambio y rediseño de procesos organizativos utilizando modelos de cambio organizativo y técnicas de reingeniería con el fin de garantizar la incorporación efectiva de las TIC | D13: 1 | E13: Evolución del sistema de información | F13: Desafíos actuales | G13: febrero | H13: 2
B14: 6 | C14: valida metodologías de gestión del cambio y rediseño de procesos organizativos utilizando modelos de cambio organizativo y técnicas de reingeniería con el fin de garantizar la incorporación efectiva de las TIC | D14: 1 | E14: Evolución del sistema de información | F14: Ejemplos de sistemas en empresas | G14: febrero | H14: 2
B15: 7 | C15: valida metodologías de gestión del cambio y rediseño de procesos organizativos utilizando modelos de cambio organizativo y técnicas de reingeniería con el fin de garantizar la incorporación efectiva de las TIC | D15: 1 | E15: Evolución del sistema de información | F15: Futuro de los sistemas de información | G15: febrero | H15: 2
B16: 8 | C16: contrasta ideas, soluciones y propuestas relacionadas con sistemas de información utilizando herramientas de comunicación efectiva con el fin de facilitar la colaboración y comprensión en la organización | D16: 1 | E16: Gestión de recursos de información | F16: Fuentes de información | G16: febrero | H16: 2
B17: 9 | C17: contrasta ideas, soluciones y propuestas relacionadas con sistemas de información utilizando herramientas de comunicación efectiva con el fin de facilitar la colaboración y comprensión en la organización | D17: 1 | E17: Gestión de recursos de información | F17: Clasificación de la información | G17: febrero | H17: 2
B18: 10 | C18: contrasta ideas, soluciones y propuestas relacionadas con sistemas de información utilizando herramientas de comunicación efectiva con el fin de facilitar la colaboración y comprensión en la organización | D18: 1 | E18: Gestión de recursos de información | F18: Herramientas de gestión | G18: febrero | H18: 3
B19: 11 | C19: contrasta ideas, soluciones y propuestas relacionadas con sistemas de información utilizando herramientas de comunicación efectiva con el fin de facilitar la colaboración y comprensión en la organización | D19: 1 | E19: Gestión de recursos de información | F19: Procesos de toma de decisiones | G19: febrero | H19: 3
B20: 12 | C20: contrasta ideas, soluciones y propuestas relacionadas con sistemas de información utilizando herramientas de comunicación efectiva con el fin de facilitar la colaboración y comprensión en la organización | D20: 1 | E20: Gestión de recursos de información | F20: Ejemplos de gestión efectiva | G20: febrero | H20: 3
... B102: 94 | C102: implementa sistemas de información organizacionales utilizando tecnologías de información y comunicación con el fin de apoyar la transformación digital y la toma de decisiones estratégicas en la empresa | D102: 5 | E102: Gamificación en educación | F102: Ventajas de las plataformas | G102: mayo | H102: 12

Sheet Semana Diagnostico
B2: Diseño de Contenido Curricular
B4: Curso | C4: ='Diseño'!C4 -> 786 - Sistemas Organizacionales y Gerenciales 1
B5: Semana | C5: 1
B6: Tiempo | C6: =B15+B22+B29+B41+B47+C48 -> #VALUE!
K8: Estos puntos son recomendaciones de los puntos a tratar durante tu presentacion, si no usaras estos eres libre de agregar mas filas para indicar que haras. En los recuadros de la derecha colocar breve resumen de lo que planeas decir. No debes ser muy especifico seran pequeñas anotaciones que te ayudaran a recordar lo que planeaste
A9: 1. Bienvenida y Presentación | G9: Tiempo Aproximado | H9: 10 min
G10: No puedes excederte mas de 15 minutos
A11: Nombre y Formacion Academica | B11: Presentacion de mi persona y formacion academica
A12: Experiencia docente y profecional | B12: Presentacion CV
A13: Rol del auxiliar dentro del curso (funciones, actividades y apoyo a los estudiantes). | B13: Ayuda por medio oficiales (UEDI y DTT)
A14: Expectativas sobre la dinámica del curso | B14: puntualidad, respeto, participación, trabajo colaborativo.
A15: Tiempo que emplearas | B15: 10 min aproximadamente
A18: 2. Evaluación de Conocimientos Previos | G18: Tiempo Aproximado | H18: =B22 -> 30 min
G19: No puedes excederte mas de 45 minutos | K19: En los recuadors de la derecha deberas colocar las preguntas que planeas realizar con sus respectivas respuestas. En el segundo recuadro deberas colocar un breve resumne de lo que tines planificado para la parte practica del curso previo al que estas impartiendo.
A20: Redactaras de 15 a 20 preguntas con sus respectivas respuestas , por lo que debes escoge los temas que evaluaras | B20: Examen de Conocimientos Previos (Tomando en cuenta pre-requisito AYD1) (VF) Un sistema de información (SI) integra personas, procesos y tecnología para apoyar decisiones. R: Verdadero. (Opción múltiple) Dato vs. Información: la información es… R: Datos procesados con contexto. (VF) Un ERP integra finanzas, inventario, compras y RR. HH. R: Verdadero. (VF) Un CRM se centra en optimizar la relación con clientes. R: Verdadero. (VF) Un SCM gestiona la cadena de suministro extremo a extremo. R: Verdadero. (Opción múltiple) Ejemplo de CRM: R: Seguimiento de oportunidades/embudo de ventas. (Opción múltiple) Ejemplo de ERP: R: Consolidación contable y control de inventarios. (VF) Business Analytics = reportes operativos únicamente. R: Falso (incluye análisis descriptivo, diagnóstico y predictivo). (Opción múltiple) En BA, un dashboard sirve para… R: Monitoreo visual de KPIs. (VF) Un caso de uso describe interacción actor–sistema para lograr un objetivo. R: Verdadero. (Opción múltiple) Arquitectura de sistemas trata de… R: Componentes, interacciones y despliegue. (VF) Gestión del conocimiento busca capturar, compartir y reutilizar know-how. R: Verdadero. (VF) Ética digital: privacidad y uso responsable de datos. R: Verdadero. (Opción múltiple) Ejemplo de integración: R: ERP + CRM via middleware/API. (VF) E-business = solo tienda en línea. R: Falso (incluye procesos y colaboración digital).
A21: Redactaras una parte practica | B21: Actividad “flash”: Clasifica 6 escenarios en ERP/CRM/SCM. Ej. “Seguimiento de tickets postventa” → CRM; “MRP y órdenes de compra” → ERP; “Ruteo de transporte” → SCM.
A22: Tiempo que emplearas | B22: 30 min
A25: 3. Presentación de los Estudiantes | G25: Tiempo Aproximado | H25: =B29 -> 20 min
G26: No puedes excederte mas de 30 minutos
A27: Seleccion al Azar de 5 Estudiantes | B27: Metodología de selección al azar: “Wheel of Names” o =RAND() en Google Sheets y ordenar por número. | K27: En el primer recuadro colocaras la metodollogia que adoptaras para la eleccion de los estudiantes. En el segundo recuadro colocaras la redaccion de las preguntas que comprendan los siguientes puntos respecto al estudiante: Nombre. Intereses y expectativas sobre el curso. Experiencia previa relacionada con el curso (si aplica). Un dato curioso sobre sí mismo. Consideras que la prueba de conociminetos previos esta acorde al conocimiento que se te brindo en su momento Que tan comodo se sintio con la prueba anterior.
A28: Preguntas que responderan los estudiantes afortunados | B28: 1) Nombre. 2) Intereses/expectativas. 3) Experiencia previa (si aplica). 4) Un dato curioso. 5) ¿La prueba diagnóstica estuvo acorde a lo visto antes? 6) ¿Qué tan cómodo se sintió?
A29: Tiempo que emplearas | B29: 20 min
A32: 4. Senso de Horarios de Calificación | G32: Tiempo Aproximado | H32: =B36 -> 5 min
A33: Deberas estar recordando que deben contestar el formulario asi mismo dejar el link fijado en la llamada | G33: Esta actividad quedara abierta hasta el fin de la clase. pero emplearas 5 min especificos para la actividad
A34: Link de google forms donde este el cuestionario | B34: https://forms.gle/MiGe8eBJiyxmu8yH6 | K34: Esta actividad te ayudara a realizar un senso de posibles horarios de calificacion y que tus estudiantes esten enterados y puedan preveer los dias de calificacion y asi mismo el horario. Deberas colocar en los reacuadros de la derecha link de Google form libre para correos intitucionales, esto para garantizar una sola respuesta por estudiante. TAmbien deberas colocar los posibles horarios y dias que tentativamente tendrias disponibles. para colocarlos en el google form.
A35: Dias y posibles Horarios de calificacion | B35: Sabado de 7:00 am - 1:00 pm y Sabado de 12:00 pm - 5:00 pm
A36: Tiempo que emplearas | B36: 5 min
A39: 4. Mostrar Programa del Curso | G39: Tiempo Aproximado | H39: =B41 -> 20 min
G40: No puedes excederte mas de 30 minutos
A41: Tiempo que emplearas | B41: 20 min
A44: 2. Evaluación de Conocimientos del Curso Actual | G44: Tiempo Aproximado | H44: =B47 -> 15 min
G45: No puedes excederte mas de 15 minutos
A46: Redactaras 20 preguntas con sus respectivas respuestas | B46: (VF) La evolución de los SI muestra mayor integración y analítica en las empresas. R: V. (OM) Un sistema funcional típico es: R: Finanzas, ventas o RR. HH. (VF) Un GIS se usa para analizar datos espaciales. R: V. (OM) Business Analytics apoya la toma de decisiones R: Con KPIs y análisis descriptivo/diagnóstico/predictivo. (VF) Gestión del conocimiento depende solo de herramientas. R: F (también procesos y cultura). (OM) Papel estratégico de las TIC: R: Habilitar ventaja competitiva y eficiencia. (VF) Global e-business implica colaboración con socios digitales. R: V. (VF) Problemas éticos: sesgos algorítmicos y privacidad de datos. R: V. (OM) Clases de SI: R: ERP, CRM, SCM, GIS, DSS, etc. (VF) La integración de sistemas reduce redundancia y mejora datos maestros. R: V. (OM) Arquitectura de sistemas: R: Capas/componentes y sus interacciones. (VF) El ciclo de vida de sistemas incluye análisis, diseño, implementación, operación. R: V. (OM) E-learning en empresas apoya… R: Formación continua y onboarding. (VF) Gamificación busca aumentar motivación mediante mecánicas de juego. R: V. (OM) Un KPI bien definido es… R: Medible, relevante y con meta temporal. (VF) Un dashboard efectivo debe alinear métricas con objetivos. R: V. (OM) Caso de uso vs user story: R: Caso de uso = interacción detallada; historia = necesidad corta. (VF) SCM coordina abastecimiento, producción y distribución. R: V. (OM) Riesgo habitual en integración: R: Silos de datos y falta de gobierno. (VF) Comunicación efectiva es clave para alinear áreas de negocio y TI. R: V.
A47: Tiempo que emplearas | B47: 15 min

Sheet S.2
B2: Diseño de la Sesión de Laboratorio
B4: Curso | C4: ='Diseño'!C4 -> 786 - Sistemas Organizacionales y Gerenciales 1
B5: Semana | C5: 2
B6: Tiempo | C6: =H10+H21+H44+H68 -> 115
B7: Ponderación | C7: =B49+B60 -> 0
B8: Validación de Tiempo | C8: =IF(H44<=0, "❌ ERROR: La Actividad 1 debe tener un tiempo mayor a 0.", IF(H21>60, "❌ ERROR: El 'Área de Conocimiento' no puede exceder los 60 min.", IF((H10+H21+H44)<100, "❌ ERROR: El tiempo total debe ser de al menos 100 min.", "✅ VALIDACIÓN CORRECTA"))) -> ✅ VALIDACIÓN CORRECTA
A10: 1. Área Actitudinal (Saber Ser) | G10: Tiempo Aproximado | H10: =B13 -> 5
G11: Tiene que estar en un rango de 3 a 5 minutos
A12: Nombre del Valor | B12: Responsabilidad
A13: Tiempo Aproximado | B13: 5
A14: Descripcion
A15: Cumplir con deberes y compromisos.
A17: Como se relaciona con los conocimientos de la sesion y se aplicaria
A18: Cumplir con deberes y compromisos que se dejan en el curso
A21: 2. Área Conocimiento (Saber) | G21: Tiempo Aproximado | H21: =SUM(D39:H42) -> 55
G22: No puede exceder los 60 minutos
A23: Competencia a desarrollar | B23: valida metodologías de gestión del cambio y rediseño de procesos organizativos utilizando modelos de cambio organizativo y técnicas de reingeniería con el fin de garantizar la incorporación efectiva de las TIC
A24: Competencia a desarrollar | B24: contrasta ideas, soluciones y propuestas relacionadas con sistemas de información utilizando herramientas de comunicación efectiva con el fin de facilitar la colaboración y comprensión en la organización
A26: 2.1 Contenido
A27: No. | B27: Unidad | D27: Tema | F27: Sub Tema
A28: 1 | B28: =IFERROR(__xludf.DUMMYFUNCTION("FILTER('Diseño'!D:D,'Diseño'!H:H=$C$5)"),1.0) -> 1 | D28: =IFERROR(__xludf.DUMMYFUNCTION("FILTER('Diseño'!E:E,'Diseño'!H:H=$C$5)"),"Evolución del sistema de información") -> Evolución del sistema de información | F28: =IFERROR(__xludf.DUMMYFUNCTION("FILTER('Diseño'!F:F,'Diseño'!H:H=$C$5)"),"Definición de sistema de información") -> Definición de sistema de información
A29: 2 | B29: =IFERROR(__xludf.DUMMYFUNCTION("""COMPUTED_VALUE"""),1.0) -> 1 | D29: =IFERROR(__xludf.DUMMYFUNCTION("""COMPUTED_VALUE"""),"Evolución del sistema de información") -> Evolución del sistema de información | F29: =IFERROR(__xludf.DUMMYFUNCTION("""COMPUTED_VALUE"""),"Historia de los sistemas de información") -> Historia de los sistemas de información
A30: 3 | B30: =IFERROR(__xludf.DUMMYFUNCTION("""COMPUTED_VALUE"""),1.0) -> 1 | D30: =IFERROR(__xludf.DUMMYFUNCTION("""COMPUTED_VALUE"""),"Evolución del sistema de información") -> Evolución del sistema de información | F30: =IFERROR(__xludf.DUMMYFUNCTION("""COMPUTED_VALUE"""),"Tipos de sistemas de información") -> Tipos de sistemas de información
A31: 4 | B31: =IFERROR(__xludf.DUMMYFUNCTION("""COMPUTED_VALUE"""),1.0) -> 1 | D31: =IFERROR(__xludf.DUMMYFUNCTION("""COMPUTED_VALUE"""),"Evolución del sistema de información") -> Evolución del sistema de información | F31: =IFERROR(__xludf.DUMMYFUNCTION("""COMPUTED_VALUE"""),"Importancia en la empresa") -> Importancia en la empresa
A32: 5 | B32: =IFERROR(__xludf.DUMMYFUNCTION("""COMPUTED_VALUE"""),1.0) -> 1 | D32: =IFERROR(__xludf.DUMMYFUNCTION("""COMPUTED_VALUE"""),"Evolución del sistema de información") -> Evolución del sistema de información | F32: =IFERROR(__xludf.DUMMYFUNCTION("""COMPUTED_VALUE"""),"Desafíos actuales") -> Desafíos actuales
A33: 6 | B33: =IFERROR(__xludf.DUMMYFUNCTION("""COMPUTED_VALUE"""),1.0) -> 1 | D33: =IFERROR(__xludf.DUMMYFUNCTION("""COMPUTED_VALUE"""),"Evolución del sistema de información") -> Evolución del sistema de información | F33: =IFERROR(__xludf.DUMMYFUNCTION("""COMPUTED_VALUE"""),"Ejemplos de sistemas en empresas") -> Ejemplos de sistemas en empresas
A34: 7 | B34: =IFERROR(__xludf.DUMMYFUNCTION("""COMPUTED_VALUE"""),1.0) -> 1 | D34: =IFERROR(__xludf.DUMMYFUNCTION("""COMPUTED_VALUE"""),"Evolución del sistema de información") -> Evolución del sistema de información | F34: =IFERROR(__xludf.DUMMYFUNCTION("""COMPUTED_VALUE"""),"Futuro de los sistemas de información") -> Futuro de los sistemas de información
B35: =IFERROR(__xludf.DUMMYFUNCTION("""COMPUTED_VALUE"""),1.0) -> 1 | D35: =IFERROR(__xludf.DUMMYFUNCTION("""COMPUTED_VALUE"""),"Gestión de recursos de información") -> Gestión de recursos de información | F35: =IFERROR(__xludf.DUMMYFUNCTION("""COMPUTED_VALUE"""),"Fuentes de información") -> Fuentes de información
A36: 2.2 Recursos Educativos | B36: =IFERROR(__xludf.DUMMYFUNCTION("""COMPUTED_VALUE"""),1.0) -> 1 | D36: =IFERROR(__xludf.DUMMYFUNCTION("""COMPUTED_VALUE"""),"Gestión de recursos de información") -> Gestión de recursos de información | F36: =IFERROR(__xludf.DUMMYFUNCTION("""COMPUTED_VALUE"""),"Clasificación de la información") -> Clasificación de la información
A38: Tipo de Recurso a utilizar | B38: Tipo | C38: Rango Aproximando | D38: Tiempo Aproximado
A39: Presentacion | B39: Obligatorio | C39: 5 a 10 minutos | D39: 10
A40: Video | B40: Obligatorio | C40: 3 a 6 minutos | D40: 5
A41: Lectura | B41: Optativo | C41: 25 minutos | D41: 25
A42: Ejercicio Demostrativo | B42: Obligatorio | C42: 15 minutos | D42: 15
A44: 3. Área de Habilidades (Saber Hacer) | G44: Tiempo Aproximado | H44: =B50 -> 40
G45: Tiene que estar en un rango de 30 a 50 minutos
A46: Actividad 1 (Obligatoria)
A47: Competencia que predomina en la actividad | B47: contrasta ideas, soluciones y propuestas relacionadas con sistemas de información utilizando herramientas de comunicación efectiva con el fin de facilitar la colaboración y comprensión en la organización
A48: Tipo de Actividad | B48: Ejercicio practico
A49: Ponderación | B49: 0
...

Sheet S.3
B2: Diseño de la Sesión de Laboratorio
B4: Curso | C4: ='Diseño'!C4 -> 786 - Sistemas Organizacionales y Gerenciales 1
B5: Semana | C5: 3
B6: Tiempo | C6: =H10+H21+H44+H68 -> 115
B7: Ponderación | C7: =B49+B60 -> 0
B8: Validación de Tiempo | C8: =IF(H44<=0, "❌ ERROR: La Actividad 1 debe tener un tiempo mayor a 0.", IF(H21>60, "❌ ERROR: El 'Área de Conocimiento' no puede exceder los 60 min.", IF((H10+H21+H44)<100, "❌ ERROR: El tiempo total debe ser de al menos 100 min.", "✅ VALIDACIÓN CORRECTA"))) -> ✅ VALIDACIÓN CORRECTA
A10: 1. Área Actitudinal (Saber Ser) | G10: Tiempo Aproximado | H10: =B13 -> 5
G11: Tiene que estar en un rango de 3 a 5 minutos
A12: Nombre del Valor | B12: Respeto
A13: Tiempo Aproximado | B13: 5
A14: Descripcion
A15: Tratar a los demás con dignidad y cortesía.
A17: Como se relaciona con los conocimientos de la sesion y se aplicaria
A18: Tratar a los demás con dignidad y cortesía , genera una cultura de respeto y de una mejor manera para poder organizar grupos.
A21: 2. Área Conocimiento (Saber) | G21: Tiempo Aproximado | H21: =SUM(D39:H42) -> 55
G22: No puede exceder los 60 minutos
A23: Competencia a desarrollar | B23: valida metodologías de gestión del cambio y rediseño de procesos organizativos utilizando modelos de cambio organizativo y técnicas de reingeniería con el fin de garantizar la incorporación efectiva de las TIC
A24: Competencia a desarrollar | B24: contrasta ideas, soluciones y propuestas relacionadas con sistemas de información utilizando herramientas de comunicación efectiva con el fin de facilitar la colaboración y comprensión en la organización
A26: 2.1 Contenido
A27: No. | B27: Unidad | D27: Tema | F27: Sub Tema
A28: 1 | B28: =IFERROR(__xludf.DUMMYFUNCTION("FILTER('Diseño'!D:D,'Diseño'!H:H=$C$5)"),1.0) -> 1 | D28: =IFERROR(__xludf.DUMMYFUNCTION("FILTER('Diseño'!E:E,'Diseño'!H:H=$C$5)"),"Gestión de recursos de información") -> Gestión de recursos de información | F28: =IFERROR(__xludf.DUMMYFUNCTION("FILTER('Diseño'!F:F,'Diseño'!H:H=$C$5)"),"Herramientas de gestión") -> Herramientas de gestión
A29: 2 | B29: =IFERROR(__xludf.DUMMYFUNCTION("""COMPUTED_VALUE"""),1.0) -> 1 | D29: =IFERROR(__xludf.DUMMYFUNCTION("""COMPUTED_VALUE"""),"Gestión de recursos de información") -> Gestión de recursos de información | F29: =IFERROR(__xludf.DUMMYFUNCTION("""COMPUTED_VALUE"""),"Procesos de toma de decisiones") -> Procesos de toma de decisiones
A30: 3 | B30: =IFERROR(__xludf.DUMMYFUNCTION("""COMPUTED_VALUE"""),1.0) -> 1 | D30: =IFERROR(__xludf.DUMMYFUNCTION("""COMPUTED_VALUE"""),"Gestión de recursos de información") -> Gestión de recursos de información | F30: =IFERROR(__xludf.DUMMYFUNCTION("""COMPUTED_VALUE"""),"Ejemplos de gestión efectiva") -> Ejemplos de gestión efectiva
A31: 4 | B31: =IFERROR(__xludf.DUMMYFUNCTION("""COMPUTED_VALUE"""),1.0) -> 1 | D31: =IFERROR(__xludf.DUMMYFUNCTION("""COMPUTED_VALUE"""),"Gestión de recursos de información") -> Gestión de recursos de información | F31: =IFERROR(__xludf.DUMMYFUNCTION("""COMPUTED_VALUE"""),"Impacto en la organización") -> Impacto en la organización
A32: 5 | B32: =IFERROR(__xludf.DUMMYFUNCTION("""COMPUTED_VALUE"""),1.0) -> 1 | D32: =IFERROR(__xludf.DUMMYFUNCTION("""COMPUTED_VALUE"""),"Gestión de recursos de información") -> Gestión de recursos de información | F32: =IFERROR(__xludf.DUMMYFUNCTION("""COMPUTED_VALUE"""),"Estudio de caso") -> Estudio de caso
A33: 6 | B33: =IFERROR(__xludf.DUMMYFUNCTION("""COMPUTED_VALUE"""),1.0) -> 1 | D33: =IFERROR(__xludf.DUMMYFUNCTION("""COMPUTED_VALUE"""),"Business Analytics") -> Business Analytics | F33: =IFERROR(__xludf.DUMMYFUNCTION("""COMPUTED_VALUE"""),"Definición de Business Analytics") -> Definición de Business Analytics
A34: 7 | B34: =IFERROR(__xludf.DUMMYFUNCTION("""COMPUTED_VALUE"""),1.0) -> 1 | D34: =IFERROR(__xludf.DUMMYFUNCTION("""COMPUTED_VALUE"""),"Business Analytics") -> Business Analytics | F34: =IFERROR(__xludf.DUMMYFUNCTION("""COMPUTED_VALUE"""),"Herramientas de análisis") -> Herramientas de análisis
A36: 2.2 Recursos Educativos
A38: Tipo de Recurso a utilizar | B38: Tipo | C38: Rango Aproximando | D38: Tiempo Aproximado
A39: Presentacion | B39: Obligatorio | C39: 5 a 10 minutos | D39: 10
A40: Video | B40: Obligatorio | C40: 3 a 6 minutos | D40: 5
A41: Lectura | B41: Optativo | C41: 25 minutos | D41: 25
A42: Ejercicio Demostrativo | B42: Obligatorio | C42: 15 minutos | D42: 15
A44: 3. Área de Habilidades (Saber Hacer) | G44: Tiempo Aproximado | H44: =B50 -> 40
G45: Tiene que estar en un rango de 30 a 50 minutos
A46: Actividad 1 (Obligatoria)
A47: Competencia que predomina en la actividad | B47: contrasta ideas, soluciones y propuestas relacionadas con sistemas de información utilizando herramientas de comunicación efectiva con el fin de facilitar la colaboración y comprensión en la organización
A48: Tipo de Actividad | B48: otros
A49: Ponderación | B49: 0
A50: Tiempo Aproximado | B50: 40
...

Sheet S.4
B2: Diseño de la Sesión de Laboratorio
B4: Curso | C4: ='Diseño'!C4 -> 786 - Sistemas Organizacionales y Gerenciales 1
B5: Semana | C5: 4
B6: Tiempo | C6: =H10+H21+H44+H68 -> 115
B7: Ponderación | C7: =B49+B60 -> 0
B8: Validación de Tiempo | C8: =IF(H44<=0, "❌ ERROR: La Actividad 1 debe tener un tiempo mayor a 0.", IF(H21>60, "❌ ERROR: El 'Área de Conocimiento' no puede exceder los 60 min.", IF((H10+H21+H44)<100, "❌ ERROR: El tiempo total debe ser de al menos 100 min.", "✅ VALIDACIÓN CORRECTA"))) -> ✅ VALIDACIÓN CORRECTA
A10: 1. Área Actitudinal (Saber Ser) | G10: Tiempo Aproximado | H10: =B13 -> 5
G11: Tiene que estar en un rango de 3 a 5 minutos
A12: Nombre del Valor | B12: Perseverancia
A13: Tiempo Aproximado | B13: 5
A14: Descripcion
A15: Valor: Mantenerse constante ante los retos.
A17: Como se relaciona con los conocimientos de la sesion y se aplicaria
A18: Al ser perseverante se puede lograr terminar el curso con una nota aprobatoria
A21: 2. Área Conocimiento (Saber) | G21: Tiempo Aproximado | H21: =SUM(D39:H42) -> 55
G22: No puede exceder los 60 minutos
A23: Competencia a desarrollar | B23: combina técnicas de trabajo en equipo y colaboración interdisciplinaria empleando metodologías ágiles de gestión de proyectos con el fin de fomentar la innovación y eficiencia organizacional
A24: Competencia a desarrollar
A26: 2.1 Contenido
A27: No. | B27: Unidad | D27: Tema | F27: Sub Tema
A28: 1 | B28: =IFERROR(__xludf.DUMMYFUNCTION("FILTER('Diseño'!D:D,'Diseño'!H:H=$C$5)"),1.0) -> 1 | D28: =IFERROR(__xludf.DUMMYFUNCTION("FILTER('Diseño'!E:E,'Diseño'!H:H=$C$5)"),"Business Analytics") -> Business Analytics | F28: =IFERROR(__xludf.DUMMYFUNCTION("FILTER('Diseño'!F:F,'Diseño'!H:H=$C$5)"),"Importancia en la toma de decisiones") -> Importancia en la toma de decisiones
A29: 2 | B29: =IFERROR(__xludf.DUMMYFUNCTION("""COMPUTED_VALUE"""),1.0) -> 1 | D29: =IFERROR(__xludf.DUMMYFUNCTION("""COMPUTED_VALUE"""),"Business Analytics") -> Business Analytics | F29: =IFERROR(__xludf.DUMMYFUNCTION("""COMPUTED_VALUE"""),"Ejemplos de Business Analytics") -> Ejemplos de Business Analytics
A30: 3 | B30: =IFERROR(__xludf.DUMMYFUNCTION("""COMPUTED_VALUE"""),1.0) -> 1 | D30: =IFERROR(__xludf.DUMMYFUNCTION("""COMPUTED_VALUE"""),"Business Analytics") -> Business Analytics | F30: =IFERROR(__xludf.DUMMYFUNCTION("""COMPUTED_VALUE"""),"Casos de éxito") -> Casos de éxito
A31: 4 | B31: =IFERROR(__xludf.DUMMYFUNCTION("""COMPUTED_VALUE"""),1.0) -> 1 | D31: =IFERROR(__xludf.DUMMYFUNCTION("""COMPUTED_VALUE"""),"Business Analytics") -> Business Analytics | F31: =IFERROR(__xludf.DUMMYFUNCTION("""COMPUTED_VALUE"""),"Integración con sistemas de información") -> Integración con sistemas de información
A32: 5 | B32: =IFERROR(__xludf.DUMMYFUNCTION("""COMPUTED_VALUE"""),1.0) -> 1 | D32: =IFERROR(__xludf.DUMMYFUNCTION("""COMPUTED_VALUE"""),"Business Analytics") -> Business Analytics | F32: =IFERROR(__xludf.DUMMYFUNCTION("""COMPUTED_VALUE"""),"Tendencias futuras") -> Tendencias futuras
A33: 6 | B33: =IFERROR(__xludf.DUMMYFUNCTION("""COMPUTED_VALUE"""),1.0) -> 1 | D33: =IFERROR(__xludf.DUMMYFUNCTION("""COMPUTED_VALUE"""),"La gestión del conocimiento") -> La gestión del conocimiento | F33: =IFERROR(__xludf.DUMMYFUNCTION("""COMPUTED_VALUE"""),"Concepto de gestión del conocimiento") -> Concepto de gestión del conocimiento
A34: 7 | B34: =IFERROR(__xludf.DUMMYFUNCTION("""COMPUTED_VALUE"""),1.0) -> 1 | D34: =IFERROR(__xludf.DUMMYFUNCTION("""COMPUTED_VALUE"""),"La gestión del conocimiento") -> La gestión del conocimiento | F34: =IFERROR(__xludf.DUMMYFUNCTION("""COMPUTED_VALUE"""),"Estrategias de gestión") -> Estrategias de gestión
A36: 2.2 Recursos Educativos
A38: Tipo de Recurso a utilizar | B38: Tipo | C38: Rango Aproximando | D38: Tiempo Aproximado
A39: Presentacion | B39: Obligatorio | C39: 5 a 10 minutos | D39: 10
A40: Video | B40: Obligatorio | C40: 3 a 6 minutos | D40: 5
A41: Lectura | B41: Optativo | C41: 25 minutos | D41: 25
A42: Ejercicio Demostrativo | B42: Obligatorio | C42: 15 minutos | D42: 15
A44: 3. Área de Habilidades (Saber Hacer) | G44: Tiempo Aproximado | H44: =B50 -> 40
G45: Tiene que estar en un rango de 30 a 50 minutos
A46: Actividad 1 (Obligatoria)
A47: Competencia que predomina en la actividad | B47: contrasta ideas, soluciones y propuestas relacionadas con sistemas de información utilizando herramientas de comunicación efectiva con el fin de facilitar la colaboración y comprensión en la organización
A48: Tipo de Actividad | B48: otros
A49: Ponderación | B49: 0
A50: Tiempo Aproximado | B50: 40
...

Sheet S.5
B2: Diseño de la Sesión de Laboratorio
B4: Curso | C4: ='Diseño'!C4 -> 786 - Sistemas Organizacionales y Gerenciales 1
B5: Semana | C5: 5
B6: Tiempo | C6: =H10+H21+H44+H68 -> 115
B7: Ponderación | C7: =B49+B60 -> 0
B8: Validación de Tiempo | C8: =IF(H44<=0, "❌ ERROR: La Actividad 1 debe tener un tiempo mayor a 0.", IF(H21>60, "❌ ERROR: El 'Área de Conocimiento' no puede exceder los 60 min.", IF((H10+H21+H44)<100, "❌ ERROR: El tiempo total debe ser de al menos 100 min.", "✅ VALIDACIÓN CORRECTA"))) -> ✅ VALIDACIÓN CORRECTA
A10: 1. Área Actitudinal (Saber Ser) | G10: Tiempo Aproximado | H10: =B13 -> 5
G11: Tiene que estar en un rango de 3 a 5 minutos
A12: Nombre del Valor | B12: Honestidad
A13: Tiempo Aproximado | B13: 5
A14: Descripcion
A15: Valor: Actuar con verdad y coherencia.
A17: Como se relaciona con los conocimientos de la sesion y se aplicaria
A18: Al actuar de forma honesta se puede integrar a la parte de la cultura organizacional para tomar el ejemplo
A21: 2. Área Conocimiento (Saber) | G21: Tiempo Aproximado | H21: =SUM(D39:H42) -> 55
G22: No puede exceder los 60 minutos
A23: Competencia a desarrollar | B23: contrasta ideas, soluciones y propuestas relacionadas con sistemas de información utilizando herramientas de comunicación efectiva con el fin de facilitar la colaboración y comprensión en la organización
A24: Competencia a desarrollar
A26: 2.1 Contenido
A27: No. | B27: Unidad | D27: Tema | F27: Sub Tema
A28: 1 | B28: =IFERROR(__xludf.DUMMYFUNCTION("FILTER('Diseño'!D:D,'Diseño'!H:H=$C$5)"),1.0) -> 1 | D28: =IFERROR(__xludf.DUMMYFUNCTION("FILTER('Diseño'!E:E,'Diseño'!H:H=$C$5)"),"La gestión del conocimiento") -> La gestión del conocimiento | F28: =IFERROR(__xludf.DUMMYFUNCTION("FILTER('Diseño'!F:F,'Diseño'!H:H=$C$5)"),"Herramientas tecnológicas") -> Herramientas tecnológicas
A29: 2 | B29: =IFERROR(__xludf.DUMMYFUNCTION("""COMPUTED_VALUE"""),1.0) -> 1 | D29: =IFERROR(__xludf.DUMMYFUNCTION("""COMPUTED_VALUE"""),"La gestión del conocimiento") -> La gestión del conocimiento | F29: =IFERROR(__xludf.DUMMYFUNCTION("""COMPUTED_VALUE"""),"Impacto en la organización") -> Impacto en la organización
A30: 3 | B30: =IFERROR(__xludf.DUMMYFUNCTION("""COMPUTED_VALUE"""),1.0) -> 1 | D30: =IFERROR(__xludf.DUMMYFUNCTION("""COMPUTED_VALUE"""),"La gestión del conocimiento") -> La gestión del conocimiento | F30: =IFERROR(__xludf.DUMMYFUNCTION("""COMPUTED_VALUE"""),"Ejemplos de gestión del conocimiento") -> Ejemplos de gestión del conocimiento
A31: 4 | B31: =IFERROR(__xludf.DUMMYFUNCTION("""COMPUTED_VALUE"""),1.0) -> 1 | D31: =IFERROR(__xludf.DUMMYFUNCTION("""COMPUTED_VALUE"""),"La gestión del conocimiento") -> La gestión del conocimiento | F31: =IFERROR(__xludf.DUMMYFUNCTION("""COMPUTED_VALUE"""),"Estudio de caso") -> Estudio de caso
A32: 5 | B32: =IFERROR(__xludf.DUMMYFUNCTION("""COMPUTED_VALUE"""),1.0) -> 1 | D32: =IFERROR(__xludf.DUMMYFUNCTION("""COMPUTED_VALUE"""),"La gestión del conocimiento") -> La gestión del conocimiento | F32: =IFERROR(__xludf.DUMMYFUNCTION("""COMPUTED_VALUE"""),"Futuro de la gestión del conocimiento") -> Futuro de la gestión del conocimiento
A33: 6 | B33: =IFERROR(__xludf.DUMMYFUNCTION("""COMPUTED_VALUE"""),2.0) -> 2 | D33: =IFERROR(__xludf.DUMMYFUNCTION("""COMPUTED_VALUE"""),"Papel estratégico de las TIC") -> Papel estratégico de las TIC | F33: =IFERROR(__xludf.DUMMYFUNCTION("""COMPUTED_VALUE"""),"Definición de TIC") -> Definición de TIC
A34: 7
A36: 2.2 Recursos Educativos
A38: Tipo de Recurso a utilizar | B38: Tipo | C38: Rango Aproximando | D38: Tiempo Aproximado
A39: Presentacion | B39: Obligatorio | C39: 5 a 10 minutos | D39: 10
A40: Video | B40: Obligatorio | C40: 3 a 6 minutos | D40: 5
A41: Lectura | B41: Optativo | C41: 25 minutos | D41: 25
A42: Ejercicio Demostrativo | B42: Obligatorio | C42: 15 minutos | D42: 15
A44: 3. Área de Habilidades (Saber Hacer) | G44: Tiempo Aproximado | H44: =B50 -> 40
G45: Tiene que estar en un rango de 30 a 50 minutos
A46: Actividad 1 (Obligatoria)
A47: Competencia que predomina en la actividad | B47: contrasta ideas, soluciones y propuestas relacionadas con sistemas de información utilizando herramientas de comunicación efectiva con el fin de facilitar la colaboración y comprensión en la organización
A48: Tipo de Actividad | B48: otros
A49: Ponderación | B49: 0
A50: Tiempo Aproximado | B50: 40
...

Sheet S.6
B2: Diseño de la Sesión de Laboratorio
B4: Curso | C4: ='Diseño'!C4 -> 786 - Sistemas Organizacionales y Gerenciales 1
B5: Semana | C5: 6
B6: Tiempo | C6: =H10+H21+H44+H68 -> 115
B7: Ponderación | C7: =B49+B60 -> 0
B8: Validación de Tiempo | C8: =IF(H44<=0, "❌ ERROR: La Actividad 1 debe tener un tiempo mayor a 0.", IF(H21>60, "❌ ERROR: El 'Área de Conocimiento' no puede exceder los 60 min.", IF((H10+H21+H44)<100, "❌ ERROR: El tiempo total debe ser de al menos 100 min.", "✅ VALIDACIÓN CORRECTA"))) -> ✅ VALIDACIÓN CORRECTA
A10: 1. Área Actitudinal (Saber Ser) | G10: Tiempo Aproximado | H10: =B13 -> 5
G11: Tiene que estar en un rango de 3 a 5 minutos
A12: Nombre del Valor | B12: Innovación
A13: Tiempo Aproximado | B13: 5
A14: Descripcion
A15: Fomentar la capacidad de adaptarse a los cambios tecnológicos y proponer soluciones creativas en un entorno empresarial global.
A17: Como se relaciona con los conocimientos de la sesion y se aplicaria
A18: Mejorar las ideas de los estudiantes y los temas revolucion en el mercado
A21: 2. Área Conocimiento (Saber) | G21: Tiempo Aproximado | H21: =SUM(D39:H42) -> 55
G22: No puede exceder los 60 minutos
A23: Competencia a desarrollar | B23: moviliza habilidades de pensamiento crítico y resolución de problemas utilizando estudios de caso empresariales con el fin de fortalecer la toma de decisiones en entornos organizacionales
A24: Competencia a desarrollar | B24: implementa sistemas de información organizacionales utilizando tecnologías de información y comunicación con el fin de apoyar la transformación digital y la toma de decisiones estratégicas en la empresa
A26: 2.1 Contenido
A27: No. | B27: Unidad | D27: Tema | F27: Sub Tema
A28: 1 | B28: =IFERROR(__xludf.DUMMYFUNCTION("FILTER('Diseño'!D:D,'Diseño'!H:H=$C$5)"),2.0) -> 2 | D28: =IFERROR(__xludf.DUMMYFUNCTION("FILTER('Diseño'!E:E,'Diseño'!H:H=$C$5)"),"Papel estratégico de las TIC") -> Papel estratégico de las TIC | F28: =IFERROR(__xludf.DUMMYFUNCTION("FILTER('Diseño'!F:F,'Diseño'!H:H=$C$5)"),"Historia de las TIC") -> Historia de las TIC
A29: 2 | B29: =IFERROR(__xludf.DUMMYFUNCTION("""COMPUTED_VALUE"""),2.0) -> 2 | D29: =IFERROR(__xludf.DUMMYFUNCTION("""COMPUTED_VALUE"""),"Papel estratégico de las TIC") -> Papel estratégico de las TIC | F29: =IFERROR(__xludf.DUMMYFUNCTION("""COMPUTED_VALUE"""),"Tipos de TIC") -> Tipos de TIC
A30: 3 | B30: =IFERROR(__xludf.DUMMYFUNCTION("""COMPUTED_VALUE"""),2.0) -> 2 | D30: =IFERROR(__xludf.DUMMYFUNCTION("""COMPUTED_VALUE"""),"Papel estratégico de las TIC") -> Papel estratégico de las TIC | F30: =IFERROR(__xludf.DUMMYFUNCTION("""COMPUTED_VALUE"""),"Importancia en la empresa") -> Importancia en la empresa
A31: 4 | B31: =IFERROR(__xludf.DUMMYFUNCTION("""COMPUTED_VALUE"""),2.0) -> 2 | D31: =IFERROR(__xludf.DUMMYFUNCTION("""COMPUTED_VALUE"""),"Papel estratégico de las TIC") -> Papel estratégico de las TIC | F31: =IFERROR(__xludf.DUMMYFUNCTION("""COMPUTED_VALUE"""),"Desafíos actuales") -> Desafíos actuales
A32: 5 | B32: =IFERROR(__xludf.DUMMYFUNCTION("""COMPUTED_VALUE"""),2.0) -> 2 | D32: =IFERROR(__xludf.DUMMYFUNCTION("""COMPUTED_VALUE"""),"Papel estratégico de las TIC") -> Papel estratégico de las TIC | F32: =IFERROR(__xludf.DUMMYFUNCTION("""COMPUTED_VALUE"""),"Ejemplos de uso de TIC en empresas") -> Ejemplos de uso de TIC en empresas
A33: 6 | B33: =IFERROR(__xludf.DUMMYFUNCTION("""COMPUTED_VALUE"""),2.0) -> 2 | D33: =IFERROR(__xludf.DUMMYFUNCTION("""COMPUTED_VALUE"""),"Papel estratégico de las TIC") -> Papel estratégico de las TIC | F33: =IFERROR(__xludf.DUMMYFUNCTION("""COMPUTED_VALUE"""),"Futuro de las TIC") -> Futuro de las TIC
A34: 7 | B34: =IFERROR(__xludf.DUMMYFUNCTION("""COMPUTED_VALUE"""),2.0) -> 2 | D34: =IFERROR(__xludf.DUMMYFUNCTION("""COMPUTED_VALUE"""),"Sistemas de información en negocios globales") -> Sistemas de información en negocios globales | F34: =IFERROR(__xludf.DUMMYFUNCTION("""COMPUTED_VALUE"""),"Definición de sistemas en negocios globales") -> Definición de sistemas en negocios globales
A36: 2.2 Recursos Educativos
A38: Tipo de Recurso a utilizar | B38: Tipo | C38: Rango Aproximando | D38: Tiempo Aproximado
A39: Presentacion | B39: Obligatorio | C39: 5 a 10 minutos | D39: 10
A40: Video | B40: Obligatorio | C40: 3 a 6 minutos | D40: 5
A41: Lectura | B41: Optativo | C41: 25 minutos | D41: 25
A42: Ejercicio Demostrativo | B42: Obligatorio | C42: 15 minutos | D42: 15
A44: 3. Área de Habilidades (Saber Hacer) | G44: Tiempo Aproximado | H44: =B50 -> 40
G45: Tiene que estar en un rango de 30 a 50 minutos
A46: Actividad 1 (Obligatoria)
A47: Competencia que predomina en la actividad | B47: implementa sistemas de información organizacionales utilizando tecnologías de información y comunicación con el fin de apoyar la transformación digital y la toma de decisiones estratégicas en la empresa
A48: Tipo de Actividad | B48: Cuestionario
A49: Ponderación | B49: 0
A50: Tiempo Aproximado | B50: 40
...

Sheet S.7
B2: Diseño de la Sesión de Laboratorio
B4: Curso | C4: ='Diseño'!C4 -> 786 - Sistemas Organizacionales y Gerenciales 1
B5: Semana | C5: 7
B6: Tiempo | C6: =H10+H21+H44+H68 -> 105
B7: Ponderación | C7: =B49+B60 -> 0
B8: Validación de Tiempo | C8: =IF(H44<=0, "❌ ERROR: La Actividad 1 debe tener un tiempo mayor a 0.", IF(H21>60, "❌ ERROR: El 'Área de Conocimiento' no puede exceder los 60 min.", IF((H10+H21+H44+H68)<100, "❌ ERROR: El tiempo total debe ser de al menos 100 min.", "✅ VALIDACIÓN CORRECTA"))) -> ✅ VALIDACIÓN CORRECTA
A10: 1. Área Actitudinal (Saber Ser) | G10: Tiempo Aproximado | H10: =B13 -> 5
G11: Tiene que estar en un rango de 3 a 5 minutos
A12: Nombre del Valor | B12: Responsabilidad
A13: Tiempo Aproximado | B13: 5
A14: Descripcion
A15: Promover la responsabilidad como valor clave al participar en entornos digitales y colaborativos, asumiendo compromisos éticos, profesionales y sociales al implementar o usar tecnologías en los negocios.
A17: Como se relaciona con los conocimientos de la sesion y se aplicaria
A18: se relaciona con los conocimientos de la sesión al implicar un compromiso ético en el diseño, implementación y uso de sistemas TIC. Se aplica al asegurar que los profesionales tomen decisiones informadas y conscientes sobre el impacto de los ERP, SCM, CRM y otros sistemas en la sociedad.
A21: 2. Área Conocimiento (Saber) | G21: Tiempo Aproximado | H21: =SUM(D39:H42) -> 60
G22: No puede exceder los 60 minutos
A23: Competencia a desarrollar | B23: moviliza habilidades de pensamiento crítico y resolución de problemas utilizando estudios de caso empresariales con el fin de fortalecer la toma de decisiones en entornos organizacionales
A24: Competencia a desarrollar | B24: diseña soluciones de sistemas de información geográfica (GIS) y de inteligencia de negocios (BI) utilizando software especializado con el fin de optimizar la visualización y análisis de datos estratégicos
A26: 2.1 Contenido
A27: No. | B27: Unidad | D27: Tema | F27: Sub Tema
A28: 1 | B28: =IFERROR(__xludf.DUMMYFUNCTION("FILTER('Diseño'!D:D,'Diseño'!H:H=$C$5)"),2.0) -> 2 | D28: =IFERROR(__xludf.DUMMYFUNCTION("FILTER('Diseño'!E:E,'Diseño'!H:H=$C$5)"),"Sistemas de información en negocios globales") -> Sistemas de información en negocios globales | F28: =IFERROR(__xludf.DUMMYFUNCTION("FILTER('Diseño'!F:F,'Diseño'!H:H=$C$5)"),"Impacto en la globalización") -> Impacto en la globalización
A29: 2 | B29: =IFERROR(__xludf.DUMMYFUNCTION("""COMPUTED_VALUE"""),2.0) -> 2 | D29: =IFERROR(__xludf.DUMMYFUNCTION("""COMPUTED_VALUE"""),"Sistemas de información en negocios globales") -> Sistemas de información en negocios globales | F29: =IFERROR(__xludf.DUMMYFUNCTION("""COMPUTED_VALUE"""),"Ejemplos de implementación") -> Ejemplos de implementación
A30: 3 | B30: =IFERROR(__xludf.DUMMYFUNCTION("""COMPUTED_VALUE"""),2.0) -> 2 | D30: =IFERROR(__xludf.DUMMYFUNCTION("""COMPUTED_VALUE"""),"Sistemas de información en negocios globales") -> Sistemas de información en negocios globales | F30: =IFERROR(__xludf.DUMMYFUNCTION("""COMPUTED_VALUE"""),"Desafíos en la integración") -> Desafíos en la integración
A31: 4 | B31: =IFERROR(__xludf.DUMMYFUNCTION("""COMPUTED_VALUE"""),2.0) -> 2 | D31: =IFERROR(__xludf.DUMMYFUNCTION("""COMPUTED_VALUE"""),"Sistemas de información en negocios globales") -> Sistemas de información en negocios globales | F31: =IFERROR(__xludf.DUMMYFUNCTION("""COMPUTED_VALUE"""),"Herramientas tecnológicas") -> Herramientas tecnológicas
A32: 5 | B32: =IFERROR(__xludf.DUMMYFUNCTION("""COMPUTED_VALUE"""),2.0) -> 2 | D32: =IFERROR(__xludf.DUMMYFUNCTION("""COMPUTED_VALUE"""),"Sistemas de información en negocios globales") -> Sistemas de información en negocios globales | F32: =IFERROR(__xludf.DUMMYFUNCTION("""COMPUTED_VALUE"""),"Impacto en la cultura empresarial") -> Impacto en la cultura empresarial
A33: 6 | B33: =IFERROR(__xludf.DUMMYFUNCTION("""COMPUTED_VALUE"""),2.0) -> 2 | D33: =IFERROR(__xludf.DUMMYFUNCTION("""COMPUTED_VALUE"""),"Sistemas de información en negocios globales") -> Sistemas de información en negocios globales | F33: =IFERROR(__xludf.DUMMYFUNCTION("""COMPUTED_VALUE"""),"Futuro de los negocios globales") -> Futuro de los negocios globales
A34: 7 | B34: =IFERROR(__xludf.DUMMYFUNCTION("""COMPUTED_VALUE"""),2.0) -> 2 | D34: =IFERROR(__xludf.DUMMYFUNCTION("""COMPUTED_VALUE"""),"Global e-business y colaboración") -> Global e-business y colaboración | F34: =IFERROR(__xludf.DUMMYFUNCTION("""COMPUTED_VALUE"""),"Definición de e-business") -> Definición de e-business
A36: 2.2 Recursos Educativos
A38: Tipo de Recurso a utilizar | B38: Tipo | C38: Rango Aproximando | D38: Tiempo Aproximado
A39: Presentacion | B39: Obligatorio | C39: 10 a 15 | D39: 15
A40: Video | B40: Obligatorio | C40: 10 a 15 | D40: 15
A41: Lectura | B41: Optativo | C41: 10 a 15 | D41: 15
A42: Ejercicio Demostrativo | B42: Obligatorio | C42: 10 a 15 | D42: 15
A44: 3. Área de Habilidades (Saber Hacer) | G44: Tiempo Aproximado | H44: =B50 -> 30
G45: Tiene que estar en un rango de 30 a 50 minutos
A46: Actividad 1 (Obligatoria)
A47: Competencia que predomina en la actividad | B47: diseña soluciones de sistemas de información geográfica (GIS) y de inteligencia de negocios (BI) utilizando software especializado con el fin de optimizar la visualización y análisis de datos estratégicos
A48: Tipo de Actividad | B48: Cuestionario
A49: Ponderación | B49: 0
A50: Tiempo Aproximado | B50: 30
...

Sheet S.8
B2: Diseño de la Sesión de Laboratorio
B4: Curso | C4: ='Diseño'!C4 -> 786 - Sistemas Organizacionales y Gerenciales 1
B5: Semana | C5: 8
B6: Tiempo | C6: =H10+H21+H44+H68 -> 105
B7: Ponderación | C7: =B49+B60 -> 0
B8: Validación de Tiempo | C8: =IF(H44<=0, "❌ ERROR: La Actividad 1 debe tener un tiempo mayor a 0.", IF(H21>60, "❌ ERROR: El 'Área de Conocimiento' no puede exceder los 60 min.", IF((H10+H21+H44+H68)<100, "❌ ERROR: El tiempo total debe ser de al menos 100 min.", "✅ VALIDACIÓN CORRECTA"))) -> ✅ VALIDACIÓN CORRECTA
A10: 1. Área Actitudinal (Saber Ser) | G10: Tiempo Aproximado | H10: =B13 -> 5
G11: Tiene que estar en un rango de 3 a 5 minutos
A12: Nombre del Valor | B12: Integriadad
A13: Tiempo Aproximado | B13: 5
A14: Descripcion
A15: Fomentar la integridad como principio clave en el uso, diseño e implementación de tecnologías, promoviendo la honestidad, la ética profesional y la coherencia entre valores y acciones en el ámbito digital.
A17: Como se relaciona con los conocimientos de la sesion y se aplicaria
A18: se relaciona con los conocimientos de la sesión al destacar la importancia de mantener la coherencia y confiabilidad de los datos y procesos en la integración de sistemas. Se aplica garantizando que las soluciones integradas funcionen de manera transparente, segura y sin comprometer la veracidad de la información.
A21: 2. Área Conocimiento (Saber) | G21: Tiempo Aproximado | H21: =SUM(D39:H42) -> 60
G22: No puede exceder los 60 minutos
A23: Competencia a desarrollar | B23: revisa la evolución de los sistemas de información en la empresa mediante el análisis de casos históricos y actuales con el fin de identificar tendencias y áreas de mejora
A24: Competencia a desarrollar | B24: diseña soluciones de sistemas de información geográfica (GIS) y de inteligencia de negocios (BI) utilizando software especializado con el fin de optimizar la visualización y análisis de datos estratégicos
A26: 2.1 Contenido
A27: No. | B27: Unidad | D27: Tema | F27: Sub Tema
A28: 1 | B28: =IFERROR(__xludf.DUMMYFUNCTION("FILTER('Diseño'!D:D,'Diseño'!H:H=$C$5)"),2.0) -> 2 | D28: =IFERROR(__xludf.DUMMYFUNCTION("FILTER('Diseño'!E:E,'Diseño'!H:H=$C$5)"),"Global e-business y colaboración") -> Global e-business y colaboración | F28: =IFERROR(__xludf.DUMMYFUNCTION("FILTER('Diseño'!F:F,'Diseño'!H:H=$C$5)"),"Estrategias de colaboración") -> Estrategias de colaboración
A29: 2 | B29: =IFERROR(__xludf.DUMMYFUNCTION("""COMPUTED_VALUE"""),2.0) -> 2 | D29: =IFERROR(__xludf.DUMMYFUNCTION("""COMPUTED_VALUE"""),"Global e-business y colaboración") -> Global e-business y colaboración | F29: =IFERROR(__xludf.DUMMYFUNCTION("""COMPUTED_VALUE"""),"Ejemplos de e-business") -> Ejemplos de e-business
A30: 3 | B30: =IFERROR(__xludf.DUMMYFUNCTION("""COMPUTED_VALUE"""),2.0) -> 2 | D30: =IFERROR(__xludf.DUMMYFUNCTION("""COMPUTED_VALUE"""),"Global e-business y colaboración") -> Global e-business y colaboración | F30: =IFERROR(__xludf.DUMMYFUNCTION("""COMPUTED_VALUE"""),"Herramientas para e-business") -> Herramientas para e-business
A31: 4 | B31: =IFERROR(__xludf.DUMMYFUNCTION("""COMPUTED_VALUE"""),2.0) -> 2 | D31: =IFERROR(__xludf.DUMMYFUNCTION("""COMPUTED_VALUE"""),"Global e-business y colaboración") -> Global e-business y colaboración | F31: =IFERROR(__xludf.DUMMYFUNCTION("""COMPUTED_VALUE"""),"Casos de éxito") -> Casos de éxito
A32: 5 | B32: =IFERROR(__xludf.DUMMYFUNCTION("""COMPUTED_VALUE"""),2.0) -> 2 | D32: =IFERROR(__xludf.DUMMYFUNCTION("""COMPUTED_VALUE"""),"Global e-business y colaboración") -> Global e-business y colaboración | F32: =IFERROR(__xludf.DUMMYFUNCTION("""COMPUTED_VALUE"""),"Desafíos en e-business") -> Desafíos en e-business
A33: 6 | B33: =IFERROR(__xludf.DUMMYFUNCTION("""COMPUTED_VALUE"""),2.0) -> 2 | D33: =IFERROR(__xludf.DUMMYFUNCTION("""COMPUTED_VALUE"""),"Global e-business y colaboración") -> Global e-business y colaboración | F33: =IFERROR(__xludf.DUMMYFUNCTION("""COMPUTED_VALUE"""),"Futuro del e-business") -> Futuro del e-business
A34: 7 | B34: =IFERROR(__xludf.DUMMYFUNCTION("""COMPUTED_VALUE"""),2.0) -> 2 | D34: =IFERROR(__xludf.DUMMYFUNCTION("""COMPUTED_VALUE"""),"Problemas éticos y sociales en sistemas") -> Problemas éticos y sociales en sistemas | F34: =IFERROR(__xludf.DUMMYFUNCTION("""COMPUTED_VALUE"""),"Definición de problemas éticos") -> Definición de problemas éticos
A36: 2.2 Recursos Educativos
A38: Tipo de Recurso a utilizar | B38: Tipo | C38: Rango Aproximando | D38: Tiempo Aproximado
A39: Presentacion | B39: Obligatorio | C39: 10 a 15 | D39: 15
A40: Video | B40: Obligatorio | C40: 10 a 15 | D40: 15
A41: Lectura | B41: Optativo | C41: 10 a 15 | D41: 15
A42: Ejercicio Demostrativo | B42: Obligatorio | C42: 10 a 15 | D42: 15
A44: 3. Área de Habilidades (Saber Hacer) | G44: Tiempo Aproximado | H44: =B50 -> 30
G45: Tiene que estar en un rango de 30 a 50 minutos
A46: Actividad 1 (Obligatoria)
A47: Competencia que predomina en la actividad | B47: moviliza habilidades de pensamiento crítico y resolución de problemas utilizando estudios de caso empresariales con el fin de fortalecer la toma de decisiones en entornos organizacionales
A48: Tipo de Actividad | B48: Cuestionario
A49: Ponderación | B49: 0
A50: Tiempo Aproximado | B50: 30
...

Sheet S.9
B2: Diseño de la Sesión de Laboratorio
B4: Curso | C4: ='Diseño'!C4 -> 786 - Sistemas Organizacionales y Gerenciales 1
B5: Semana | C5: 9
B6: Tiempo | C6: =H10+H21+H44+H68 -> 105
B7: Ponderación | C7: =B49+B60 -> 0
B8: Validación de Tiempo | C8: =IF(H44<=0, "❌ ERROR: La Actividad 1 debe tener un tiempo mayor a 0.", IF(H21>60, "❌ ERROR: El 'Área de Conocimiento' no puede exceder los 60 min.", IF((H10+H21+H44+H68)<100, "❌ ERROR: El tiempo total debe ser de al menos 100 min.", "✅ VALIDACIÓN CORRECTA"))) -> ✅ VALIDACIÓN CORRECTA
A10: 1. Área Actitudinal (Saber Ser) | G10: Tiempo Aproximado | H10: =B13 -> 5
G11: Tiene que estar en un rango de 3 a 5 minutos
A12: Nombre del Valor | B12: Eficiencia
A13: Tiempo Aproximado | B13: 5
A14: Descripcion
A15: Promover la eficiencia como valor esencial al diseñar, integrar y utilizar sistemas de información, buscando siempre optimizar recursos, procesos y resultados dentro de una organización
A17: Como se relaciona con los conocimientos de la sesion y se aplicaria
A18: Eficiencia se relaciona con los conocimientos de la sesión al enfocarse en cómo una buena arquitectura de sistemas y una gestión adecuada del ciclo de vida optimizan recursos y procesos. Se aplica al diseñar sistemas que mejoren el rendimiento organizacional con menor esfuerzo y mayor efectividad.
A21: 2. Área Conocimiento (Saber) | G21: Tiempo Aproximado | H21: =SUM(D39:H42) -> 60
G22: No puede exceder los 60 minutos
A23: Competencia a desarrollar | B23: revisa la evolución de los sistemas de información en la empresa mediante el análisis de casos históricos y actuales con el fin de identificar tendencias y áreas de mejora
A24: Competencia a desarrollar | B24: combina técnicas de trabajo en equipo y colaboración interdisciplinaria empleando metodologías ágiles de gestión de proyectos con el fin de fomentar la innovación y eficiencia organizacional
A26: 2.1 Contenido
A27: No. | B27: Unidad | D27: Tema | F27: Sub Tema
A28: 1 | B28: =IFERROR(__xludf.DUMMYFUNCTION("FILTER('Diseño'!D:D,'Diseño'!H:H=$C$5)"),2.0) -> 2 | D28: =IFERROR(__xludf.DUMMYFUNCTION("FILTER('Diseño'!E:E,'Diseño'!H:H=$C$5)"),"Problemas éticos y sociales en sistemas") -> Problemas éticos y sociales en sistemas | F28: =IFERROR(__xludf.DUMMYFUNCTION("FILTER('Diseño'!F:F,'Diseño'!H:H=$C$5)"),"Ejemplos de problemas éticos") -> Ejemplos de problemas éticos
A29: 2 | B29: =IFERROR(__xludf.DUMMYFUNCTION("""COMPUTED_VALUE"""),2.0) -> 2 | D29: =IFERROR(__xludf.DUMMYFUNCTION("""COMPUTED_VALUE"""),"Problemas éticos y sociales en sistemas") -> Problemas éticos y sociales en sistemas | F29: =IFERROR(__xludf.DUMMYFUNCTION("""COMPUTED_VALUE"""),"Impacto social de las TIC") -> Impacto social de las TIC
A30: 3 | B30: =IFERROR(__xludf.DUMMYFUNCTION("""COMPUTED_VALUE"""),2.0) -> 2 | D30: =IFERROR(__xludf.DUMMYFUNCTION("""COMPUTED_VALUE"""),"Problemas éticos y sociales en sistemas") -> Problemas éticos y sociales en sistemas | F30: =IFERROR(__xludf.DUMMYFUNCTION("""COMPUTED_VALUE"""),"Casos de estudio") -> Casos de estudio
A31: 4 | B31: =IFERROR(__xludf.DUMMYFUNCTION("""COMPUTED_VALUE"""),2.0) -> 2 | D31: =IFERROR(__xludf.DUMMYFUNCTION("""COMPUTED_VALUE"""),"Problemas éticos y sociales en sistemas") -> Problemas éticos y sociales en sistemas | F31: =IFERROR(__xludf.DUMMYFUNCTION("""COMPUTED_VALUE"""),"Desafíos éticos en la implementación") -> Desafíos éticos en la implementación
A32: 5 | B32: =IFERROR(__xludf.DUMMYFUNCTION("""COMPUTED_VALUE"""),2.0) -> 2 | D32: =IFERROR(__xludf.DUMMYFUNCTION("""COMPUTED_VALUE"""),"Problemas éticos y sociales en sistemas") -> Problemas éticos y sociales en sistemas | F32: =IFERROR(__xludf.DUMMYFUNCTION("""COMPUTED_VALUE"""),"Futuro de la ética en TIC") -> Futuro de la ética en TIC
A33: 6 | B33: =IFERROR(__xludf.DUMMYFUNCTION("""COMPUTED_VALUE"""),2.0) -> 2 | D33: =IFERROR(__xludf.DUMMYFUNCTION("""COMPUTED_VALUE"""),"Problemas éticos y sociales en sistemas") -> Problemas éticos y sociales en sistemas | F33: =IFERROR(__xludf.DUMMYFUNCTION("""COMPUTED_VALUE"""),"Conclusiones sobre problemas éticos") -> Conclusiones sobre problemas éticos
A34: 7 | B34: =IFERROR(__xludf.DUMMYFUNCTION("""COMPUTED_VALUE"""),3.0) -> 3 | D34: =IFERROR(__xludf.DUMMYFUNCTION("""COMPUTED_VALUE"""),"Clases de sistemas de información") -> Clases de sistemas de información | F34: =IFERROR(__xludf.DUMMYFUNCTION("""COMPUTED_VALUE"""),"Sistemas funcionales") -> Sistemas funcionales
B35: =IFERROR(__xludf.DUMMYFUNCTION("""COMPUTED_VALUE"""),3.0) -> 3 | D35: =IFERROR(__xludf.DUMMYFUNCTION("""COMPUTED_VALUE"""),"Clases de sistemas de información") -> Clases de sistemas de información | F35: =IFERROR(__xludf.DUMMYFUNCTION("""COMPUTED_VALUE"""),"ERP") -> ERP
A36: 2.2 Recursos Educativos
A38: Tipo de Recurso a utilizar | B38: Tipo | C38: Rango Aproximando | D38: Tiempo Aproximado
A39: Presentacion | B39: Obligatorio | C39: 10 a 15 | D39: 15
A40: Video | B40: Obligatorio | C40: 10 a 15 | D40: 15
A41: Lectura | B41: Optativo | C41: 10 a 15 | D41: 15
A42: Ejercicio Demostrativo | B42: Obligatorio | C42: 10 a 15 | D42: 15
A44: 3. Área de Habilidades (Saber Hacer) | G44: Tiempo Aproximado | H44: =B50 -> 30
G45: Tiene que estar en un rango de 30 a 50 minutos
A46: Actividad 1 (Obligatoria)
A47: Competencia que predomina en la actividad | B47: implementa sistemas de información organizacionales utilizando tecnologías de información y comunicación con el fin de apoyar la transformación digital y la toma de decisiones estratégicas en la empresa
A48: Tipo de Actividad | B48: Cuestionario
A49: Ponderación | B49: 0
...

Sheet S.10
B2: Diseño de la Sesión de Laboratorio
B4: Curso | C4: ='Diseño'!C4 -> 786 - Sistemas Organizacionales y Gerenciales 1
B5: Semana | C5: 10
B6: Tiempo | C6: =H10+H21+H44+H68 -> 105
B7: Ponderación | C7: =B49+B60 -> 0
B8: Validación de Tiempo | C8: =IF(H44<=0, "❌ ERROR: La Actividad 1 debe tener un tiempo mayor a 0.", IF(H21>60, "❌ ERROR: El 'Área de Conocimiento' no puede exceder los 60 min.", IF((H10+H21+H44+H68)<100, "❌ ERROR: El tiempo total debe ser de al menos 100 min.", "✅ VALIDACIÓN CORRECTA"))) -> ✅ VALIDACIÓN CORRECTA
A10: 1. Área Actitudinal (Saber Ser) | G10: Tiempo Aproximado | H10: =B13 -> 5
G11: Tiene que estar en un rango de 3 a 5 minutos
A12: Nombre del Valor | B12: Planificación
A13: Tiempo Aproximado | B13: 5
A14: Descripcion
A15: Fomentar la planificación como valor clave para desarrollar, mantener y evolucionar sistemas de información de forma ordenada, sostenible y alineada con los objetivos de la organización.
A17: Como se relaciona con los conocimientos de la sesion y se aplicaria
A18: Se relaciona al aplicar el ciclo de vida en la planificación y aprovechar el e-learning como apoyo en los procesos educativos y tecnológicos.
A21: 2. Área Conocimiento (Saber) | G21: Tiempo Aproximado | H21: =SUM(D39:H42) -> 60
G22: No puede exceder los 60 minutos
A23: Competencia a desarrollar | B23: revisa la evolución de los sistemas de información en la empresa mediante el análisis de casos históricos y actuales con el fin de identificar tendencias y áreas de mejora
A24: Competencia a desarrollar | B24: moviliza habilidades de pensamiento crítico y resolución de problemas utilizando estudios de caso empresariales con el fin de fortalecer la toma de decisiones en entornos organizacionales
A26: 2.1 Contenido
A27: No. | B27: Unidad | D27: Tema | F27: Sub Tema
A28: 1 | B28: =IFERROR(__xludf.DUMMYFUNCTION("FILTER('Diseño'!D:D,'Diseño'!H:H=$C$5)"),"#REF!") -> #REF! | D28: =IFERROR(__xludf.DUMMYFUNCTION("FILTER('Diseño'!E:E,'Diseño'!H:H=$C$5)"),"#REF!") -> #REF! | F28: =IFERROR(__xludf.DUMMYFUNCTION("FILTER('Diseño'!F:F,'Diseño'!H:H=$C$5)"),"SCM") -> SCM
A29: 2 | F29: =IFERROR(__xludf.DUMMYFUNCTION("""COMPUTED_VALUE"""),"CRM") -> CRM
A30: 3 | F30: =IFERROR(__xludf.DUMMYFUNCTION("""COMPUTED_VALUE"""),"Sistemas distribuidos") -> Sistemas distribuidos
A31: 4 | F31: =IFERROR(__xludf.DUMMYFUNCTION("""COMPUTED_VALUE"""),"GIS") -> GIS
A32: 5 | F32: =IFERROR(__xludf.DUMMYFUNCTION("""COMPUTED_VALUE"""),"Conclusiones sobre clases de sistemas") -> Conclusiones sobre clases de sistemas
A33: 6 | F33: =IFERROR(__xludf.DUMMYFUNCTION("""COMPUTED_VALUE"""),"Definición de integración") -> Definición de integración
A34: 7 | F34: =IFERROR(__xludf.DUMMYFUNCTION("""COMPUTED_VALUE"""),"Beneficios de la integración") -> Beneficios de la integración
F35: =IFERROR(__xludf.DUMMYFUNCTION("""COMPUTED_VALUE"""),"Ejemplos de integración") -> Ejemplos de integración
A36: 2.2 Recursos Educativos | F36: =IFERROR(__xludf.DUMMYFUNCTION("""COMPUTED_VALUE"""),"Herramientas de integración") -> Herramientas de integración
F37: =IFERROR(__xludf.DUMMYFUNCTION("""COMPUTED_VALUE"""),"Desafíos en la integración") -> Desafíos en la integración
A38: Tipo de Recurso a utilizar | B38: Tipo | C38: Rango Aproximando | D38: Tiempo Aproximado
A39: Presentacion | B39: Obligatorio | C39: 10 a 15 | D39: 15
A40: Video | B40: Obligatorio | C40: 10 a 15 | D40: 15
A41: Lectura | B41: Optativo | C41: 10 a 15 | D41: 15
A42: Ejercicio Demostrativo | B42: Obligatorio | C42: 10 a 15 | D42: 15
A44: 3. Área de Habilidades (Saber Hacer) | G44: Tiempo Aproximado | H44: =B50 -> 30
G45: Tiene que estar en un rango de 30 a 50 minutos
A46: Actividad 1 (Obligatoria)
A47: Competencia que predomina en la actividad | B47: revisa la evolución de los sistemas de información en la empresa mediante el análisis de casos históricos y actuales con el fin de identificar tendencias y áreas de mejora
A48: Tipo de Actividad | B48: Cuestionario
...

Sheet S.11
B2: Diseño de la Sesión de Laboratorio
B4: Curso | C4: ='Diseño'!C4 -> 786 - Sistemas Organizacionales y Gerenciales 1
B5: Semana | C5: 11
B6: Tiempo | C6: =H10+H21+H49+H73 -> 105
B7: Ponderación | C7: =B54+B65 -> 0
B8: Validación de Tiempo | C8: =IF(H49<=0, "❌ ERROR: La Actividad 1 debe tener un tiempo mayor a 0.", IF(H21>60, "❌ ERROR: El 'Área de Conocimiento' no puede exceder los 60 min.", IF((H10+H21+H49)<100, "❌ ERROR: El tiempo total debe ser de al menos 100 min.", "✅ VALIDACIÓN CORRECTA"))) -> ❌ ERROR: El tiempo total debe ser de al menos 100 min.
A10: 1. Área Actitudinal (Saber Ser) | G10: Tiempo Aproximado | H10: =B13 -> 5
G11: Tiene que estar en un rango de 3 a 5 minutos
A12: Nombre del Valor | B12: Compromiso
A13: Tiempo Aproximado | B13: 5
A14: Descripcion
A15: Fomentar el compromiso como valor esencial en entornos educativos digitales, donde la motivación, la constancia y la participación activa son claves para el aprendizaje efectivo
A17: Como se relaciona con los conocimientos de la sesion y se aplicaria
A18: El compromiso consiste en aplicar lo aprendido sobre e-learning y gamificación, aprovechando sus ventajas y herramientas para mejorar la enseñanza y mantener la motivación en los procesos educativos.
A21: 2. Área Conocimiento (Saber) | G21: Tiempo Aproximado | H21: =SUM(D44:H47) -> 60
G22: No puede exceder los 60 minutos
A23: Competencia a desarrollar | B23: moviliza habilidades de pensamiento crítico y resolución de problemas utilizando estudios de caso empresariales con el fin de fortalecer la toma de decisiones en entornos organizacionales
A24: Competencia a desarrollar | B24: contrasta ideas, soluciones y propuestas relacionadas con sistemas de información utilizando herramientas de comunicación efectiva con el fin de facilitar la colaboración y comprensión en la organización
A26: 2.1 Contenido
A27: No. | B27: Unidad | D27: Tema | F27: Sub Tema
A28: 1 | B28: =IFERROR(__xludf.DUMMYFUNCTION("FILTER('Diseño'!D:D,'Diseño'!H:H=$C$5)"),3.0) -> 3 | D28: =IFERROR(__xludf.DUMMYFUNCTION("FILTER('Diseño'!E:E,'Diseño'!H:H=$C$5)"),"Arquitectura de sistemas") -> Arquitectura de sistemas | F28: =IFERROR(__xludf.DUMMYFUNCTION("FILTER('Diseño'!F:F,'Diseño'!H:H=$C$5)"),"Ejemplos de arquitecturas") -> Ejemplos de arquitecturas
A29: 2 | B29: =IFERROR(__xludf.DUMMYFUNCTION("""COMPUTED_VALUE"""),3.0) -> 3 | D29: =IFERROR(__xludf.DUMMYFUNCTION("""COMPUTED_VALUE"""),"Arquitectura de sistemas") -> Arquitectura de sistemas | F29: =IFERROR(__xludf.DUMMYFUNCTION("""COMPUTED_VALUE"""),"Herramientas para arquitecturas") -> Herramientas para arquitecturas
A30: 3 | B30: =IFERROR(__xludf.DUMMYFUNCTION("""COMPUTED_VALUE"""),3.0) -> 3 | D30: =IFERROR(__xludf.DUMMYFUNCTION("""COMPUTED_VALUE"""),"Arquitectura de sistemas") -> Arquitectura de sistemas | F30: =IFERROR(__xludf.DUMMYFUNCTION("""COMPUTED_VALUE"""),"Impacto en la organización") -> Impacto en la organización
A31: 4 | B31: =IFERROR(__xludf.DUMMYFUNCTION("""COMPUTED_VALUE"""),3.0) -> 3 | D31: =IFERROR(__xludf.DUMMYFUNCTION("""COMPUTED_VALUE"""),"Arquitectura de sistemas") -> Arquitectura de sistemas | F31: =IFERROR(__xludf.DUMMYFUNCTION("""COMPUTED_VALUE"""),"Futuro de la arquitectura de sistemas") -> Futuro de la arquitectura de sistemas
